<?xml version="1.0" ?>
<!--
  Pilotage demo world (increment 1b): a diff-drive vehicle_blue (from the
  upstream diff_drive.sdf demo) with an onboard forward camera rigidly
  attached to the chassis, plus a few colored primitive obstacles so the
  camera view visibly changes while driving.

  Command:
    gz topic -t "/model/vehicle_blue/cmd_vel" -m gz.msgs.Twist -p "linear: {x: 0.5}, angular: {z: 0.05}"

  Telemetry:
    gz topic -e -t /model/vehicle_blue/odometry

  Camera:
    gz topic -e -t /camera
-->
<sdf version="1.6">
  <world name="pilotage_yard">

    <physics name="1ms" type="ignored">
      <max_step_size>0.001</max_step_size>
      <real_time_factor>1.0</real_time_factor>
    </physics>
    <plugin
      filename="gz-sim-physics-system"
      name="gz::sim::systems::Physics">
    </plugin>
    <plugin
      filename="gz-sim-sensors-system"
      name="gz::sim::systems::Sensors">
      <render_engine>ogre2</render_engine>
    </plugin>
    <plugin
      filename="gz-sim-user-commands-system"
      name="gz::sim::systems::UserCommands">
    </plugin>
    <plugin
      filename="gz-sim-scene-broadcaster-system"
      name="gz::sim::systems::SceneBroadcaster">
    </plugin>

    <scene>
      <ambient>1.0 1.0 1.0</ambient>
      <background>0.8 0.8 0.8</background>
      <grid>false</grid>
    </scene>

    <light type="directional" name="sun">
      <cast_shadows>true</cast_shadows>
      <pose>0 0 10 0 0 0</pose>
      <diffuse>1 1 1 1</diffuse>
      <specular>0.5 0.5 0.5 1</specular>
      <attenuation>
        <range>1000</range>
        <constant>0.9</constant>
        <linear>0.01</linear>
        <quadratic>0.001</quadratic>
      </attenuation>
      <direction>-0.5 0.1 -0.9</direction>
    </light>

    <model name="ground_plane">
      <static>true</static>
      <link name="link">
        <collision name="collision">
          <geometry>
            <plane>
              <normal>0 0 1</normal>
              <size>100 100</size>
            </plane>
          </geometry>
        </collision>
        <visual name="visual">
          <geometry>
            <plane>
              <normal>0 0 1</normal>
              <size>100 100</size>
            </plane>
          </geometry>
          <material>
            <ambient>0.8 0.8 0.8 1</ambient>
            <diffuse>0.8 0.8 0.8 1</diffuse>
            <specular>0.8 0.8 0.8 1</specular>
          </material>
        </visual>
      </link>
    </model>

    <!-- Colored primitive obstacles ahead of vehicle_blue's start pose and
         heading, so the onboard camera view visibly changes while driving
         forward. -->
    <model name="obstacle_red_box">
      <static>true</static>
      <pose>4 3.4 0.5 0 0 0</pose>
      <link name="link">
        <visual name="visual">
          <geometry>
            <box>
              <size>1 1 1</size>
            </box>
          </geometry>
          <material>
            <ambient>1 0 0 1</ambient>
            <diffuse>1 0 0 1</diffuse>
            <specular>1 0 0 1</specular>
          </material>
        </visual>
        <collision name="collision">
          <geometry>
            <box>
              <size>1 1 1</size>
            </box>
          </geometry>
        </collision>
      </link>
    </model>

    <model name="obstacle_green_sphere">
      <static>true</static>
      <pose>5 1.3 0.4 0 0 0</pose>
      <link name="link">
        <visual name="visual">
          <geometry>
            <sphere>
              <radius>0.4</radius>
            </sphere>
          </geometry>
          <material>
            <ambient>0 1 0 1</ambient>
            <diffuse>0 1 0 1</diffuse>
            <specular>0 1 0 1</specular>
          </material>
        </visual>
        <collision name="collision">
          <geometry>
            <sphere>
              <radius>0.4</radius>
            </sphere>
          </geometry>
        </collision>
      </link>
    </model>

    <model name="obstacle_yellow_cylinder">
      <static>true</static>
      <pose>7 2.6 0.5 0 0 0</pose>
      <link name="link">
        <visual name="visual">
          <geometry>
            <cylinder>
              <radius>0.3</radius>
              <length>1</length>
            </cylinder>
          </geometry>
          <material>
            <ambient>1 1 0 1</ambient>
            <diffuse>1 1 0 1</diffuse>
            <specular>1 1 0 1</specular>
          </material>
        </visual>
        <collision name="collision">
          <geometry>
            <cylinder>
              <radius>0.3</radius>
              <length>1</length>
            </cylinder>
          </geometry>
        </collision>
      </link>
    </model>

    <model name='vehicle_blue'>
      <pose>0 2 0.325 0 -0 0</pose>

      <link name='chassis'>
        <pose>-0.151427 -0 0.175 0 -0 0</pose>
        <inertial>
          <mass>1.14395</mass>
          <inertia>
            <ixx>0.126164</ixx>
            <ixy>0</ixy>
            <ixz>0</ixz>
            <iyy>0.416519</iyy>
            <iyz>0</iyz>
            <izz>0.481014</izz>
          </inertia>
        </inertial>
        <visual name='visual'>
          <geometry>
            <box>
              <size>2.01142 1 0.568726</size>
            </box>
          </geometry>
          <material>
            <ambient>0.5 0.5 1.0 1</ambient>
            <diffuse>0.5 0.5 1.0 1</diffuse>
            <specular>0.0 0.0 1.0 1</specular>
          </material>
        </visual>
        <collision name='collision'>
          <geometry>
            <box>
              <size>2.01142 1 0.568726</size>
            </box>
          </geometry>
        </collision>

        <!-- Onboard forward-facing camera, rigidly attached to the chassis
             (ADR-0008: capture as close as practical to the render
             pipeline; here, mounted directly on the vehicle body). -->
        <sensor name="camera" type="camera">
          <pose>1.1 0 0.3 0 0 0</pose>
          <camera>
            <horizontal_fov>1.396</horizontal_fov>
            <image>
              <width>320</width>
              <height>240</height>
            </image>
            <clip>
              <near>0.1</near>
              <far>100</far>
            </clip>
          </camera>
          <always_on>1</always_on>
          <update_rate>30</update_rate>
          <visualize>true</visualize>
          <topic>camera</topic>
        </sensor>

        <!-- Chase camera, rigidly attached to the same chassis link so it
             moves and yaws with the vehicle: a 3rd-person view positioned
             behind and above, pitched down to frame the vehicle plus the
             scene ahead. -->
        <sensor name="chase_camera" type="camera">
          <pose>-3.0 0 1.8 0 0.30 0</pose>
          <camera>
            <horizontal_fov>1.6</horizontal_fov>
            <image>
              <width>320</width>
              <height>240</height>
            </image>
            <clip>
              <near>0.1</near>
              <far>100</far>
            </clip>
          </camera>
          <always_on>1</always_on>
          <update_rate>30</update_rate>
          <visualize>true</visualize>
          <topic>chase_camera</topic>
        </sensor>
      </link>

      <link name='left_wheel'>
        <pose>0.554283 0.625029 -0.025 -1.5707 0 0</pose>
        <inertial>
          <mass>2</mass>
          <inertia>
            <ixx>0.145833</ixx>
            <ixy>0</ixy>
            <ixz>0</ixz>
            <iyy>0.145833</iyy>
            <iyz>0</iyz>
            <izz>0.125</izz>
          </inertia>
        </inertial>
        <visual name='visual'>
          <geometry>
            <sphere>
              <radius>0.3</radius>
            </sphere>
          </geometry>
          <material>
            <ambient>0.2 0.2 0.2 1</ambient>
            <diffuse>0.2 0.2 0.2 1</diffuse>
            <specular>0.2 0.2 0.2 1</specular>
          </material>
        </visual>
        <collision name='collision'>
          <geometry>
            <sphere>
              <radius>0.3</radius>
            </sphere>
          </geometry>
          <surface>
            <friction>
              <ode>
                <mu>1</mu>
                <mu2>1</mu2>
                <slip1>0.035</slip1>
                <slip2>0</slip2>
                <fdir1>0 0 1</fdir1>
              </ode>
              <bullet>
                <friction>1</friction>
                <friction2>1</friction2>
                <rolling_friction>0.1</rolling_friction>
              </bullet>
            </friction>
          </surface>
        </collision>
      </link>

      <link name='right_wheel'>
        <pose>0.554282 -0.625029 -0.025 -1.5707 0 0</pose>
        <inertial>
          <mass>2</mass>
          <inertia>
            <ixx>0.145833</ixx>
            <ixy>0</ixy>
            <ixz>0</ixz>
            <iyy>0.145833</iyy>
            <iyz>0</iyz>
            <izz>0.125</izz>
          </inertia>
        </inertial>
        <visual name='visual'>
          <geometry>
            <sphere>
              <radius>0.3</radius>
            </sphere>
          </geometry>
          <material>
            <ambient>0.2 0.2 0.2 1</ambient>
            <diffuse>0.2 0.2 0.2 1</diffuse>
            <specular>0.2 0.2 0.2 1</specular>
          </material>
        </visual>
        <collision name='collision'>
          <geometry>
            <sphere>
              <radius>0.3</radius>
            </sphere>
          </geometry>
          <surface>
            <friction>
              <ode>
                <mu>1</mu>
                <mu2>1</mu2>
                <slip1>0.035</slip1>
                <slip2>0</slip2>
                <fdir1>0 0 1</fdir1>
              </ode>
              <bullet>
                <friction>1</friction>
                <friction2>1</friction2>
                <rolling_friction>0.1</rolling_friction>
              </bullet>
            </friction>
          </surface>
        </collision>
      </link>

      <link name='caster'>
        <pose>-0.957138 -0 -0.125 0 -0 0</pose>
        <inertial>
          <mass>1</mass>
          <inertia>
            <ixx>0.1</ixx>
            <ixy>0</ixy>
            <ixz>0</ixz>
            <iyy>0.1</iyy>
            <iyz>0</iyz>
            <izz>0.1</izz>
          </inertia>
        </inertial>
        <visual name='visual'>
          <geometry>
            <sphere>
              <radius>0.2</radius>
            </sphere>
          </geometry>
          <material>
            <ambient>0.2 0.2 0.2 1</ambient>
            <diffuse>0.2 0.2 0.2 1</diffuse>
            <specular>0.2 0.2 0.2 1</specular>
          </material>
        </visual>
        <collision name='collision'>
          <geometry>
            <sphere>
              <radius>0.2</radius>
            </sphere>
          </geometry>
        </collision>
      </link>

      <joint name='left_wheel_joint' type='revolute'>
        <parent>chassis</parent>
        <child>left_wheel</child>
        <axis>
          <xyz>0 0 1</xyz>
          <limit>
            <lower>-1.79769e+308</lower>
            <upper>1.79769e+308</upper>
          </limit>
        </axis>
      </joint>

      <joint name='right_wheel_joint' type='revolute'>
        <parent>chassis</parent>
        <child>right_wheel</child>
        <axis>
          <xyz>0 0 1</xyz>
          <limit>
            <lower>-1.79769e+308</lower>
            <upper>1.79769e+308</upper>
          </limit>
        </axis>
      </joint>

      <joint name='caster_wheel' type='ball'>
        <parent>chassis</parent>
        <child>caster</child>
      </joint>

      <plugin
        filename="gz-sim-diff-drive-system"
        name="gz::sim::systems::DiffDrive">
        <left_joint>left_wheel_joint</left_joint>
        <right_joint>right_wheel_joint</right_joint>
        <wheel_separation>1.25</wheel_separation>
        <wheel_radius>0.3</wheel_radius>
        <odom_publish_frequency>30</odom_publish_frequency>
        <max_linear_acceleration>1</max_linear_acceleration>
        <min_linear_acceleration>-1</min_linear_acceleration>
        <max_angular_acceleration>2</max_angular_acceleration>
        <min_angular_acceleration>-2</min_angular_acceleration>
        <max_linear_velocity>0.5</max_linear_velocity>
        <min_linear_velocity>-0.5</min_linear_velocity>
        <max_angular_velocity>1</max_angular_velocity>
        <min_angular_velocity>-1</min_angular_velocity>
      </plugin>

    </model>

  </world>
</sdf>
